<?xml version="1.0" ?>
<!-- =================================================================================== -->
<!-- |    This document was autogenerated by xacro from rsp.urdf.xacro                 | -->
<!-- |    EDITING THIS FILE BY HAND IS NOT RECOMMENDED                                 | -->
<!-- =================================================================================== -->
<robot name="RSP">
<link name="base"/>
 
<link name="robot_base_link">
  <visual>
  <origin xyz="0 0 0.0455"/>
  <geometry>
    <cylinder length="0.091" radius="0.05"/>
  </geometry>
  <material name="blue">
    <color rgba="0.0 0.0 0.8 1.0"/>
  </material>
  </visual>
  <collision>
    <origin xyz="0 0 0.5"/>
    <geometry>
      <cylinder length="0.091" radius="0.05"/>
    </geometry>
    <material name="blue">
      <color rgba="0.0 0.0 0.8 1.0"/>
    </material>
  </collision>
</link>

<link name="robot_base_link_2">
  <visual>
  <origin xyz="0 0 0.03875"/>
  <geometry>
    <box size="0.085 0.1 0.0775"/>
  </geometry>
  <material name="blue">
    <color rgba="0.0 0.0 0.8 1.0"/>
  </material>
  </visual>
  <collision>
    <origin xyz="0 0 0.5"/>
    <geometry>
      <box size="0.085 0.1 0.0775"/>
    </geometry>
    <material name="blue">
      <color rgba="0.0 0.0 0.8 1.0"/>
    </material>
  </collision>
</link>

<link name="robot_shoulder_link">
  <visual>
    <origin xyz="0 0 0.0675"/>
    <geometry>
      <cylinder length="0.135" radius="0.0425"/>
    </geometry>
    <material name="white">
      <color rgba="0.8 0.8 0.8 1.0"/>
    </material>
  </visual>
  <collision>
    <origin xyz="0 0 0.5"/>
    <geometry>
      <cylinder length="0.1955" radius="0.06"/>
    </geometry>
    <material name="white">
      <color rgba="0.8 0.8 0.8 1.0"/>
    </material>
  </collision>
</link>


<link name="robot_elbow_link">
  <visual>
    <origin xyz="0.017 0 0.03025"/>
    <geometry>
      <box size="0.089 0.1 0.0605"/>
    </geometry>
    <material name="blue">
      <color rgba="0.0 0.0 0.8 1.0"/>
    </material>
  </visual>
  <collision>
    <origin xyz="0 0 0.5"/>
    <geometry>
      <box size="0.089 0.1 0.0605"/>
    </geometry>
    <material name="blue">
      <color rgba="0.0 0.0 0.8 1.0"/>
    </material>
  </collision>
</link>

<link name="robot_wrist1_link">
  <visual>
    <origin xyz="0 0 0.0"/>
    <geometry>
      <box size="0.0585 0.07 0.045"/>
    </geometry>
    <material name="white">
      <color rgba="0.8 0.8 0.8 1.0"/>
    </material>
  </visual>
  <collision>
    <origin xyz="0 0 0.5"/>
    <geometry>
      <box size="0.0585 0.07 0.045"/>
    </geometry>
    <material name="white">
      <color rgba="0.8 0.8 0.8 1.0"/>
    </material>
  </collision>
</link>



<link name="robot_wrist2_link">
  <visual>
    <origin xyz="0.035 0 0"/>
    <geometry>
      <box size="0.07 0.07 0.045"/>
    </geometry>
    <material name="blue">
    <color rgba="0.0 0.0 0.8 1.0"/>
    </material>
  </visual>
  <collision>
    <origin xyz="0 0 0.5"/>
    <geometry>
      <box size="0.07 0.07 0.045"/>
    </geometry>
    <material name="blue">
      <color rgba="0.0 0.0 0.8 1.0"/>
    </material>
  </collision>
</link>
   

  <!-- <link name="robot_tool_link">
<visual>
<origin xyz="0 0 0.05"/>
<geometry>
<cylinder length="0.1" radius="0.1"/>
</geometry>
<material name="white">
<color rgba="0.8 0.8 0.8 1.0"/>
</material>
</visual>
<collision>
<origin xyz="0 0 0.5"/>
<geometry>
<cylinder length="0.1" radius="0.1"/>
</geometry>
<material name="white">
<color rgba="0.8 0.8 0.8 1.0"/>
</material>
</collision>
</link> -->
 
 
<joint name="robot_base" type="fixed">
  <parent link="base"/>
  <child link="robot_base_link"/>
  <origin rpy="0 0 0" xyz="0 0 0"/>
</joint>

<joint name="robot_joint1" type="revolute">
  <parent link="robot_base_link"/>
  <child link="robot_base_link_2"/>
  <origin rpy="0 0 0" xyz="0 0 0.091"/>
  <axis xyz="0.0 0.0 1.0"/>
  <limit effort="10" lower="-3.00" upper="3.00" velocity="1"/>
</joint>
 
<joint name="robot_joint2" type="revolute">
  <parent link="robot_base_link_2"/>
  <child link="robot_shoulder_link"/>
  <origin rpy="0 0 0" xyz="0 0 0.0445"/>
  <axis xyz="0.0 1.0 0.0"/>
  <limit effort="10" lower="-1.20" upper="1.50" velocity="1"/>
</joint>

<joint name="robot_joint3" type="revolute">
  <parent link="robot_shoulder_link"/>
  <child link="robot_elbow_link"/>
  <origin rpy="0 0 0" xyz="0 0 0.135"/>
  <axis xyz="0.0 1.0 0.0"/>
  <limit effort="10" lower="-2.30" upper="1.20" velocity="1"/>
</joint>

<joint name="robot_joint4" type="revolute">
  <parent link="robot_elbow_link"/>
  <child link="robot_wrist1_link"/>
  <origin rpy="0 0 0" xyz="0.091 0 0.03025"/>
  <axis xyz="1.0 0.0 0.0"/>
  <limit effort="10" lower="-2.90" upper="2.90" velocity="1"/>
</joint>

<joint name="robot_joint5" type="revolute">
  <parent link="robot_wrist1_link"/>
  <child link="robot_wrist2_link"/>
  <origin rpy="0 0 0" xyz="0.02925 0 0"/>
  <axis xyz="0.0 1.0 0.0"/>
  <limit effort="10" lower="2.00" upper="2.00" velocity="1"/>
</joint>

  <!-- <joint name="robot_joint6" type="revolute">
<parent link="robot_wrist2_link"/>
<child link="robot_tool_link"/>
<origin rpy="0 0 0" xyz="0 0 0.2"/>
<axis xyz="0.0 0.0 1.0"/>
<limit effort="10" lower="-1" upper="1" velocity="1"/>
</joint>
  -->

<link name="world"/>
<joint name="robot_base_world" type="fixed">
  <parent link="world"/>
  <child link="base"/>
  <origin rpy="0 0 0" xyz="0.0 0.0 0"/>
</joint>
</robot>